Workbook

Sheet ภาพรวมและสถิติ
A1: 📊 รายงานสรุปผลการสอบวัดผลสัมฤทธิ์ปลายภาคเรียน (Final Examination)
A2: รหัสวิชา 21909-1006 พื้นฐานการสร้างเว็บไซต์ | ระดับชั้น ปวช. 1 ชทค. (ห้อง 1 และ 2) | ภาคเรียนที่ 1 ปีการศึกษา 2569
A4: 📌 สรุปสถิติผลการสอบตอนที่ 1 (ปรนัย 30 ข้อ 30 คะแนน) เปรียบเทียบระหว่างห้อง
A5: รายการสถิติ | B5: ห้อง 1 | C5: ห้อง 2 | D5: รวมทั้ง 2 ห้อง | E5: เกณฑ์อ้างอิง / หมายเหตุ
A6: จำนวนนักเรียนทั้งหมดในทะเบียน | B6: 18 คน | C6: 16 คน | D6: 34 คน | E6: รหัส 001 - 035
A7: จำนวนนักเรียนที่เข้าสอบ | B7: 16 คน (88.89%) | C7: 15 คน (93.75%) | D7: 31 คน (91.18%) | E7: ส่งกระดาษคำตอบครบ 31 แผ่น
A8: จำนวนนักเรียนที่ขาดสอบ | B8: 2 คน (11.11%) | C8: 1 คน (6.25%) | D8: 3 คน (8.82%) | E8: รหัส 008, 014 (ห้อง 1), 025 (ห้อง 2)
A9: คะแนนเต็ม (ปรนัย ตอนที่ 1) | B9: 30 คะแนน | C9: 30 คะแนน | D9: 30 คะแนน | E9: 30 ข้อ (ข้อละ 1 คะแนน)
A10: คะแนนเฉลี่ย (Mean) | B10: =ROUND(AVERAGE('คะแนนรวม 2 ห้อง (34 คน)'!G7:G24), 2) | C10: =ROUND(AVERAGE('คะแนนรวม 2 ห้อง (34 คน)'!G25:G40), 2) | D10: =ROUND(AVERAGE('คะแนนรวม 2 ห้อง (34 คน)'!G7:G40), 2) | E10: คิดจากผู้เข้าสอบ
A11: คะแนนสูงสุด (Max) | B11: =MAX('คะแนนรวม 2 ห้อง (34 คน)'!G7:G24) | C11: =MAX('คะแนนรวม 2 ห้อง (34 คน)'!G25:G40) | D11: =MAX('คะแนนรวม 2 ห้อง (34 คน)'!G7:G40) | E11: คะแนนสูงสุดทั้งสองห้อง
A12: คะแนนต่ำสุด (Min) | B12: =MIN('คะแนนรวม 2 ห้อง (34 คน)'!G7:G24) | C12: =MIN('คะแนนรวม 2 ห้อง (34 คน)'!G25:G40) | D12: =MIN('คะแนนรวม 2 ห้อง (34 คน)'!G7:G40) | E12: คะแนนต่ำสุดทั้งสองห้อง
A13: ส่วนเบี่ยงเบนมาตรฐาน (S.D.) | B13: =ROUND(STDEV.P('คะแนนรวม 2 ห้อง (34 คน)'!G7:G24), 2) | C13: =ROUND(STDEV.P('คะแนนรวม 2 ห้อง (34 คน)'!G25:G40), 2) | D13: =ROUND(STDEV.P('คะแนนรวม 2 ห้อง (34 คน)'!G7:G40), 2) | E13: ประชากรผู้เข้าสอบ
A14: จำนวนนักเรียนที่ผ่านเกณฑ์ (≥ 15 คะแนน / 50%) | B14: =COUNTIF('คะแนนรวม 2 ห้อง (34 คน)'!G7:G24, ">=15") | C14: =COUNTIF('คะแนนรวม 2 ห้อง (34 คน)'!G25:G40, ">=15") | D14: =COUNTIF('คะแนนรวม 2 ห้อง (34 คน)'!G7:G40, ">=15") | E14: เกณฑ์ผ่าน 50% ของคะแนนเต็ม
A15: ร้อยละการผ่านเกณฑ์ | B15: =ROUND(B14/16*100, 2) & "%" | C15: =ROUND(C14/15*100, 2) & "%" | D15: =ROUND(D14/31*100, 2) & "%" | E15: เทียบกับจำนวนผู้เข้าสอบ
A18: 📈 การกระจายตัวของระดับคะแนน (Score Distribution)
A19: ช่วงคะแนน (เต็ม 30) | B19: ระดับผลการเรียนรู้ | C19: ห้อง 1 (คน) | D19: ห้อง 2 (คน) | E19: รวม (คน) | F19: ร้อยละสะสม
A20: 25 - 30 คะแนน | B20: ดีเยี่ยม (Excellent) | C20: =COUNTIFS('คะแนนรวม 2 ห้อง (34 คน)'!G7:G24, ">=25", 'คะแนนรวม 2 ห้อง (34 คน)'!G7:G24, "<=30") | D20: =COUNTIFS('คะแนนรวม 2 ห้อง (34 คน)'!G25:G40, ">=25", 'คะแนนรวม 2 ห้อง (34 คน)'!G25:G40, "<=30") | E20: =SUM(C20:D20) | F20: =ROUND(E20/31*100, 1) & "%"
A21: 20 - 24 คะแนน | B21: ดีมาก (Very Good) | C21: =COUNTIFS('คะแนนรวม 2 ห้อง (34 คน)'!G7:G24, ">=20", 'คะแนนรวม 2 ห้อง (34 คน)'!G7:G24, "<25") | D21: =COUNTIFS('คะแนนรวม 2 ห้อง (34 คน)'!G25:G40, ">=20", 'คะแนนรวม 2 ห้อง (34 คน)'!G25:G40, "<25") | E21: =SUM(C21:D21) | F21: =ROUND(E21/31*100, 1) & "%"
A22: 15 - 19 คะแนน | B22: ผ่านเกณฑ์ (Fair/Pass) | C22: =COUNTIFS('คะแนนรวม 2 ห้อง (34 คน)'!G7:G24, ">=15", 'คะแนนรวม 2 ห้อง (34 คน)'!G7:G24, "<20") | D22: =COUNTIFS('คะแนนรวม 2 ห้อง (34 คน)'!G25:G40, ">=15", 'คะแนนรวม 2 ห้อง (34 คน)'!G25:G40, "<20") | E22: =SUM(C22:D22) | F22: =ROUND(E22/31*100, 1) & "%"
A23: 10 - 14 คะแนน | B23: ควรปรับปรุง (Needs Improvement) | C23: =COUNTIFS('คะแนนรวม 2 ห้อง (34 คน)'!G7:G24, ">=10", 'คะแนนรวม 2 ห้อง (34 คน)'!G7:G24, "<15") | D23: =COUNTIFS('คะแนนรวม 2 ห้อง (34 คน)'!G25:G40, ">=10", 'คะแนนรวม 2 ห้อง (34 คน)'!G25:G40, "<15") | E23: =SUM(C23:D23) | F23: =ROUND(E23/31*100, 1) & "%"
A24: 0 - 9 คะแนน | B24: ต้องได้รับการแก้ไข (Unsatisfactory) | C24: =COUNTIFS('คะแนนรวม 2 ห้อง (34 คน)'!G7:G24, ">=0", 'คะแนนรวม 2 ห้อง (34 คน)'!G7:G24, "<10") | D24: =COUNTIFS('คะแนนรวม 2 ห้อง (34 คน)'!G25:G40, ">=0", 'คะแนนรวม 2 ห้อง (34 คน)'!G25:G40, "<10") | E24: =SUM(C24:D24) | F24: =ROUND(E24/31*100, 1) & "%"
A25: รวมผู้เข้าสอบทั้งหมด | B25: - | C25: =SUM(C20:C24) | D25: =SUM(D20:D24) | E25: =SUM(E20:E24) | F25: 100.0%
A28: 🏆 สรุปสถิติผลการสอบปลายภาครวม (ปรนัย 30 + อัตนัย 20 = เต็ม 50 คะแนน)
A29: รายการสถิติ | B29: ห้อง 1 | C29: ห้อง 2 | D29: รวมทั้ง 2 ห้อง | E29: เกณฑ์อ้างอิง / หมายเหตุ
A30: คะแนนเต็มรวม (ปลายภาค) | B30: 50 คะแนน | C30: 50 คะแนน | D30: 50 คะแนน | E30: ปรนัย 30 + อัตนัย 20
A31: คะแนนเฉลี่ยรวม (Mean) | B31: =ROUND(AVERAGE('คะแนนรวม 2 ห้อง (34 คน)'!I7:I24), 2) | C31: =ROUND(AVERAGE('คะแนนรวม 2 ห้อง (34 คน)'!I25:I40), 2) | D31: =ROUND(AVERAGE('คะแนนรวม 2 ห้อง (34 คน)'!I7:I40), 2) | E31: คิดจากผู้เข้าสอบ
A32: คะแนนสูงสุด (Max) | B32: =MAX('คะแนนรวม 2 ห้อง (34 คน)'!I7:I24) | C32: =MAX('คะแนนรวม 2 ห้อง (34 คน)'!I25:I40) | D32: =MAX('คะแนนรวม 2 ห้อง (34 คน)'!I7:I40) | E32: คะแนนสูงสุดทั้งสองห้อง
A33: คะแนนต่ำสุด (Min) | B33: =MIN('คะแนนรวม 2 ห้อง (34 คน)'!I7:I24) | C33: =MIN('คะแนนรวม 2 ห้อง (34 คน)'!I25:I40) | D33: =MIN('คะแนนรวม 2 ห้อง (34 คน)'!I7:I40) | E33: คะแนนต่ำสุดทั้งสองห้อง
A34: ส่วนเบี่ยงเบนมาตรฐาน (S.D.) | B34: =ROUND(STDEV.P('คะแนนรวม 2 ห้อง (34 คน)'!I7:I24), 2) | C34: =ROUND(STDEV.P('คะแนนรวม 2 ห้อง (34 คน)'!I25:I40), 2) | D34: =ROUND(STDEV.P('คะแนนรวม 2 ห้อง (34 คน)'!I7:I40), 2) | E34: ประชากรผู้เข้าสอบ
A35: จำนวนนักเรียนที่ผ่านเกณฑ์ (≥ 25 คะแนน / 50%) | B35: =COUNTIF('คะแนนรวม 2 ห้อง (34 คน)'!I7:I24, ">=25") | C35: =COUNTIF('คะแนนรวม 2 ห้อง (34 คน)'!I25:I40, ">=25") | D35: =COUNTIF('คะแนนรวม 2 ห้อง (34 คน)'!I7:I40, ">=25") | E35: เกณฑ์ผ่าน 50% ของคะแนนเต็ม 50
A36: ร้อยละการผ่านเกณฑ์ | B36: =ROUND(B35/16*100, 2) & "%" | C36: =ROUND(C35/15*100, 2) & "%" | D36: =ROUND(D35/31*100, 2) & "%" | E36: เทียบกับจำนวนผู้เข้าสอบ
A38: 📈 การกระจายตัวของระดับคะแนนปลายภาครวม (เต็ม 50 คะแนน)
A39: ช่วงคะแนน (เต็ม 50) | B39: ระดับผลการเรียนรู้ | C39: ห้อง 1 (คน) | D39: ห้อง 2 (คน) | E39: รวม (คน) | F39: ร้อยละสะสม
A40: 40 - 50 คะแนน | B40: ดีเยี่ยม (Excellent) | C40: =COUNTIFS('คะแนนรวม 2 ห้อง (34 คน)'!I7:I24, ">=40", 'คะแนนรวม 2 ห้อง (34 คน)'!I7:I24, "<=50") | D40: =COUNTIFS('คะแนนรวม 2 ห้อง (34 คน)'!I25:I40, ">=40", 'คะแนนรวม 2 ห้อง (34 คน)'!I25:I40, "<=50") | E40: =SUM(C40:D40) | F40: =ROUND(E40/31*100, 1) & "%"
A41: 30 - 39 คะแนน | B41: ดีมาก (Very Good) | C41: =COUNTIFS('คะแนนรวม 2 ห้อง (34 คน)'!I7:I24, ">=30", 'คะแนนรวม 2 ห้อง (34 คน)'!I7:I24, "<40") | D41: =COUNTIFS('คะแนนรวม 2 ห้อง (34 คน)'!I25:I40, ">=30", 'คะแนนรวม 2 ห้อง (34 คน)'!I25:I40, "<40") | E41: =SUM(C41:D41) | F41: =ROUND(E41/31*100, 1) & "%"
A42: 25 - 29 คะแนน | B42: ผ่านเกณฑ์ (Fair/Pass) | C42: =COUNTIFS('คะแนนรวม 2 ห้อง (34 คน)'!I7:I24, ">=25", 'คะแนนรวม 2 ห้อง (34 คน)'!I7:I24, "<30") | D42: =COUNTIFS('คะแนนรวม 2 ห้อง (34 คน)'!I25:I40, ">=25", 'คะแนนรวม 2 ห้อง (34 คน)'!I25:I40, "<30") | E42: =SUM(C42:D42) | F42: =ROUND(E42/31*100, 1) & "%"
A43: 20 - 24 คะแนน | B43: ควรปรับปรุง (Needs Improvement) | C43: =COUNTIFS('คะแนนรวม 2 ห้อง (34 คน)'!I7:I24, ">=20", 'คะแนนรวม 2 ห้อง (34 คน)'!I7:I24, "<25") | D43: =COUNTIFS('คะแนนรวม 2 ห้อง (34 คน)'!I25:I40, ">=20", 'คะแนนรวม 2 ห้อง (34 คน)'!I25:I40, "<25") | E43: =SUM(C43:D43) | F43: =ROUND(E43/31*100, 1) & "%"
A44: 0 - 19 คะแนน | B44: ต้องได้รับการแก้ไข (Unsatisfactory) | C44: =COUNTIFS('คะแนนรวม 2 ห้อง (34 คน)'!I7:I24, ">=0", 'คะแนนรวม 2 ห้อง (34 คน)'!I7:I24, "<20") | D44: =COUNTIFS('คะแนนรวม 2 ห้อง (34 คน)'!I25:I40, ">=0", 'คะแนนรวม 2 ห้อง (34 คน)'!I25:I40, "<20") | E44: =SUM(C44:D44) | F44: =ROUND(E44/31*100, 1) & "%"
A45: รวมผู้เข้าสอบทั้งหมด | B45: - | C45: =SUM(C40:C44) | D45: =SUM(D40:D44) | E45: =SUM(E40:E44) | F45: 100.0%

Sheet คะแนนรวม 2 ห้อง (34 คน)
A1: 📋 ตารางสรุปคะแนนสอบปลายภาคเรียน (เรียงตามลำดับรหัส 001 - 035 ครบทั้ง 34 คน)
A2: วิชา 21909-1006 พื้นฐานการสร้างเว็บไซต์ | ระดับชั้น ปวช. 1 ชทค. (ห้อง 1 และ 2) | ปีการศึกษา 2569
A4: ข้อมูลนักศึกษา | G4: คะแนนสอบปลายภาคเรียน (Final) | J4: ผลการประเมินและสถานะ
A5: ลำดับรวม | B5: ห้อง | C5: เลขที่ | D5: รหัสนักศึกษา | E5: รหัส (3 ตัว) | F5: ชื่อ - นามสกุล | G5: ตอนที่ 1 ปรนัย (เต็ม 30) | H5: ตอนที่ 2 อัตนัย (เต็ม 20) | I5: รวมปลายภาค (เต็ม 50) | J5: ร้อยละ (เต็ม 50) | K5: ลำดับที่ (Rank) | L5: สถานะเข้าสอบ | M5: ไฟล์กระดาษคำตอบ
F6: คะแนนเต็ม | G6: 30 | H6: 20 | I6: 50 | J6: 100.0%
A7: 1 | B7: ห้อง 1 | C7: 1 | D7: 69219090001 | E7: 001 | F7: นายกฤศมน บุญเปี่ยม | G7: 20 | H7: 4 | I7: =IF(COUNT(G7:H7)>0, SUM(G7:H7), "-") | J7: =IF(ISNUMBER(I7), ROUND(I7/$I$6*100, 2) & "%", "-") | K7: =IF(ISNUMBER(I7), RANK(I7, $I$7:$I$40), "-") | L7: เข้าสอบ | M7: S__8118291_0.jpg
A8: 2 | B8: ห้อง 1 | C8: 2 | D8: 69219090002 | E8: 002 | F8: เด็กชายกษธณชล การรักเรียน | G8: 14 | H8: 4 | I8: =IF(COUNT(G8:H8)>0, SUM(G8:H8), "-") | J8: =IF(ISNUMBER(I8), ROUND(I8/$I$6*100, 2) & "%", "-") | K8: =IF(ISNUMBER(I8), RANK(I8, $I$7:$I$40), "-") | L8: เข้าสอบ | M8: S__8118284_0.jpg
A9: 3 | B9: ห้อง 1 | C9: 3 | D9: 69219090003 | E9: 003 | F9: นางสาวกัญญ์วรา ทองดี | G9: 26 | H9: 18 | I9: =IF(COUNT(G9:H9)>0, SUM(G9:H9), "-") | J9: =IF(ISNUMBER(I9), ROUND(I9/$I$6*100, 2) & "%", "-") | K9: =IF(ISNUMBER(I9), RANK(I9, $I$7:$I$40), "-") | L9: เข้าสอบ | M9: S__8118292_0.jpg
A10: 4 | B10: ห้อง 1 | C10: 4 | D10: 69219090004 | E10: 004 | F10: นายกันธรักษ์ พานทอง | G10: 18 | H10: 5 | I10: =IF(COUNT(G10:H10)>0, SUM(G10:H10), "-") | J10: =IF(ISNUMBER(I10), ROUND(I10/$I$6*100, 2) & "%", "-") | K10: =IF(ISNUMBER(I10), RANK(I10, $I$7:$I$40), "-") | L10: เข้าสอบ | M10: S__8118288_0.jpg
A11: 5 | B11: ห้อง 1 | C11: 5 | D11: 69219090005 | E11: 005 | F11: เด็กชายคุณานนต์ พิมพ์จันทร์ | G11: 27 | H11: 5 | I11: =IF(COUNT(G11:H11)>0, SUM(G11:H11), "-") | J11: =IF(ISNUMBER(I11), ROUND(I11/$I$6*100, 2) & "%", "-") | K11: =IF(ISNUMBER(I11), RANK(I11, $I$7:$I$40), "-") | L11: เข้าสอบ | M11: S__8118286_0.jpg
A12: 6 | B12: ห้อง 1 | C12: 6 | D12: 69219090006 | E12: 006 | F12: เด็กชายเฉลิมวงศ์ มะลิใย | G12: 22 | H12: 4 | I12: =IF(COUNT(G12:H12)>0, SUM(G12:H12), "-") | J12: =IF(ISNUMBER(I12), ROUND(I12/$I$6*100, 2) & "%", "-") | K12: =IF(ISNUMBER(I12), RANK(I12, $I$7:$I$40), "-") | L12: เข้าสอบ | M12: S__8118280_0.jpg
A13: 7 | B13: ห้อง 1 | C13: 7 | D13: 69219090007 | E13: 007 | F13: นางสาวชลดา เรือนแก้ว | G13: 15 | H13: 8.5 | I13: =IF(COUNT(G13:H13)>0, SUM(G13:H13), "-") | J13: =IF(ISNUMBER(I13), ROUND(I13/$I$6*100, 2) & "%", "-") | K13: =IF(ISNUMBER(I13), RANK(I13, $I$7:$I$40), "-") | L13: เข้าสอบ | M13: S__8118285_0.jpg
A14: 8 | B14: ห้อง 1 | C14: 8 | D14: 69219090008 | E14: 008 | F14: นายณัฐกรณ์ กองทอง | G14: - | H14: - | I14: - | J14: - | K14: - | L14: ขาดสอบ | M14: -
A15: 9 | B15: ห้อง 1 | C15: 9 | D15: 69219090009 | E15: 009 | F15: นายณัฐพล ทวีทรัพย์ | G15: 17 | H15: 4 | I15: =IF(COUNT(G15:H15)>0, SUM(G15:H15), "-") | J15: =IF(ISNUMBER(I15), ROUND(I15/$I$6*100, 2) & "%", "-") | K15: =IF(ISNUMBER(I15), RANK(I15, $I$7:$I$40), "-") | L15: เข้าสอบ | M15: S__8118289_0.jpg
A16: 10 | B16: ห้อง 1 | C16: 10 | D16: 69219090010 | E16: 010 | F16: นายต้นตระการ เพชรภู่ | G16: 6 | H16: 0 | I16: =IF(COUNT(G16:H16)>0, SUM(G16:H16), "-") | J16: =IF(ISNUMBER(I16), ROUND(I16/$I$6*100, 2) & "%", "-") | K16: =IF(ISNUMBER(I16), RANK(I16, $I$7:$I$40), "-") | L16: เข้าสอบ | M16: S__8118281_0.jpg
A17: 11 | B17: ห้อง 1 | C17: 11 | D17: 69219090011 | E17: 011 | F17: นายตฤณ ตาดทอง | G17: 25 | H17: 5 | I17: =IF(COUNT(G17:H17)>0, SUM(G17:H17), "-") | J17: =IF(ISNUMBER(I17), ROUND(I17/$I$6*100, 2) & "%", "-") | K17: =IF(ISNUMBER(I17), RANK(I17, $I$7:$I$40), "-") | L17: เข้าสอบ | M17: S__8118278_0.jpg
A18: 12 | B18: ห้อง 1 | C18: 12 | D18: 69219090012 | E18: 012 | F18: นายธนพัฒน์ บุญเรือง | G18: 22 | H18: 12 | I18: =IF(COUNT(G18:H18)>0, SUM(G18:H18), "-") | J18: =IF(ISNUMBER(I18), ROUND(I18/$I$6*100, 2) & "%", "-") | K18: =IF(ISNUMBER(I18), RANK(I18, $I$7:$I$40), "-") | L18: เข้าสอบ | M18: S__8118283_0.jpg
A19: 13 | B19: ห้อง 1 | C19: 13 | D19: 69219090013 | E19: 013 | F19: นายธีรภัทร วาสิทธิ์เทพ | G19: 17 | H19: 5 | I19: =IF(COUNT(G19:H19)>0, SUM(G19:H19), "-") | J19: =IF(ISNUMBER(I19), ROUND(I19/$I$6*100, 2) & "%", "-") | K19: =IF(ISNUMBER(I19), RANK(I19, $I$7:$I$40), "-") | L19: เข้าสอบ | M19: S__8118282_0.jpg
A20: 14 | B20: ห้อง 1 | C20: 14 | D20: 69219090014 | E20: 014 | F20: นายภูเบต ควันทอง | G20: - | H20: - | I20: - | J20: - | K20: - | L20: ขาดสอบ | M20: -
A21: 15 | B21: ห้อง 1 | C21: 15 | D21: 69219090015 | E21: 015 | F21: นายภูวพิศิษฐ์ ใหลสกุล | G21: 26 | H21: 19 | I21: =IF(COUNT(G21:H21)>0, SUM(G21:H21), "-") | J21: =IF(ISNUMBER(I21), ROUND(I21/$I$6*100, 2) & "%", "-") | K21: =IF(ISNUMBER(I21), RANK(I21, $I$7:$I$40), "-") | L21: เข้าสอบ | M21: S__8118290_0.jpg
A22: 16 | B22: ห้อง 1 | C22: 16 | D22: 69219090016 | E22: 016 | F22: นางสาวมินตา บินอามัด | G22: 10 | H22: 7 | I22: =IF(COUNT(G22:H22)>0, SUM(G22:H22), "-") | J22: =IF(ISNUMBER(I22), ROUND(I22/$I$6*100, 2) & "%", "-") | K22: =IF(ISNUMBER(I22), RANK(I22, $I$7:$I$40), "-") | L22: เข้าสอบ | M22: S__8118293_0.jpg
A23: 17 | B23: ห้อง 1 | C23: 17 | D23: 69219090017 | E23: 017 | F23: นายอัรฮัม ยูนุ | G23: 26 | H23: 5 | I23: =IF(COUNT(G23:H23)>0, SUM(G23:H23), "-") | J23: =IF(ISNUMBER(I23), ROUND(I23/$I$6*100, 2) & "%", "-") | K23: =IF(ISNUMBER(I23), RANK(I23, $I$7:$I$40), "-") | L23: เข้าสอบ | M23: S__8118279_0.jpg
A24: 18 | B24: ห้อง 1 | C24: 18 | D24: 69219090018 | E24: 018 | F24: นายอานนท์ณัฏฐ์ ไวพจน์ | G24: 18 | H24: 8 | I24: =IF(COUNT(G24:H24)>0, SUM(G24:H24), "-") | J24: =IF(ISNUMBER(I24), ROUND(I24/$I$6*100, 2) & "%", "-") | K24: =IF(ISNUMBER(I24), RANK(I24, $I$7:$I$40), "-") | L24: เข้าสอบ | M24: S__8118277_0.jpg
A25: 19 | B25: ห้อง 2 | C25: 1 | D25: 69219090020 | E25: 020 | F25: นายชุติวัต สุขมั่น | G25: 15 | H25: 1 | I25: =IF(COUNT(G25:H25)>0, SUM(G25:H25), "-") | J25: =IF(ISNUMBER(I25), ROUND(I25/$I$6*100, 2) & "%", "-") | K25: =IF(ISNUMBER(I25), RANK(I25, $I$7:$I$40), "-") | L25: เข้าสอบ | M25: S__8118296_0.jpg
A26: 20 | B26: ห้อง 2 | C26: 2 | D26: 69219090021 | E26: 021 | F26: เด็กชายณัพร รัตนสุวรรณ | G26: 11 | H26: 4 | I26: =IF(COUNT(G26:H26)>0, SUM(G26:H26), "-") | J26: =IF(ISNUMBER(I26), ROUND(I26/$I$6*100, 2) & "%", "-") | K26: =IF(ISNUMBER(I26), RANK(I26, $I$7:$I$40), "-") | L26: เข้าสอบ | M26: S__8118300_0.jpg
A27: 21 | B27: ห้อง 2 | C27: 3 | D27: 69219090022 | E27: 022 | F27: นายตุลยวัต ทาสีทอง | G27: 19 | H27: 16 | I27: =IF(COUNT(G27:H27)>0, SUM(G27:H27), "-") | J27: =IF(ISNUMBER(I27), ROUND(I27/$I$6*100, 2) & "%", "-") | K27: =IF(ISNUMBER(I27), RANK(I27, $I$7:$I$40), "-") | L27: เข้าสอบ | M27: S__8118304_0.jpg
A28: 22 | B28: ห้อง 2 | C28: 4 | D28: 69219090023 | E28: 023 | F28: เด็กชายธนกฤต แก้วตา | G28: 22 | H28: 8 | I28: =IF(COUNT(G28:H28)>0, SUM(G28:H28), "-") | J28: =IF(ISNUMBER(I28), ROUND(I28/$I$6*100, 2) & "%", "-") | K28: =IF(ISNUMBER(I28), RANK(I28, $I$7:$I$40), "-") | L28: เข้าสอบ | M28: S__8118301_0.jpg
A29: 23 | B29: ห้อง 2 | C29: 5 | D29: 69219090024 | E29: 024 | F29: นายธเนศพล กันเมือง | G29: 16 | H29: 7 | I29: =IF(COUNT(G29:H29)>0, SUM(G29:H29), "-") | J29: =IF(ISNUMBER(I29), ROUND(I29/$I$6*100, 2) & "%", "-") | K29: =IF(ISNUMBER(I29), RANK(I29, $I$7:$I$40), "-") | L29: เข้าสอบ | M29: S__8118294_0.jpg
A30: 24 | B30: ห้อง 2 | C30: 6 | D30: 69219090025 | E30: 025 | F30: นายนรากร จันทร์กล่ำ | G30: - | H30: - | I30: - | J30: - | K30: - | L30: ขาดสอบ | M30: -
A31: 25 | B31: ห้อง 2 | C31: 7 | D31: 69219090026 | E31: 026 | F31: นายนราวิชญ์ ทองระคนธ์ | G31: 19 | H31: 6 | I31: =IF(COUNT(G31:H31)>0, SUM(G31:H31), "-") | J31: =IF(ISNUMBER(I31), ROUND(I31/$I$6*100, 2) & "%", "-") | K31: =IF(ISNUMBER(I31), RANK(I31, $I$7:$I$40), "-") | L31: เข้าสอบ | M31: S__8118297_0.jpg
A32: 26 | B32: ห้อง 2 | C32: 8 | D32: 69219090027 | E32: 027 | F32: นายนันทพงศ์ ช่ออุบล | G32: 8 | H32: 0 | I32: =IF(COUNT(G32:H32)>0, SUM(G32:H32), "-") | J32: =IF(ISNUMBER(I32), ROUND(I32/$I$6*100, 2) & "%", "-") | K32: =IF(ISNUMBER(I32), RANK(I32, $I$7:$I$40), "-") | L32: เข้าสอบ | M32: S__8118309.jpg
A33: 27 | B33: ห้อง 2 | C33: 9 | D33: 69219090028 | E33: 028 | F33: เด็กชายพงศ์พัทธ์ โสดา | G33: 22 | H33: 15 | I33: =IF(COUNT(G33:H33)>0, SUM(G33:H33), "-") | J33: =IF(ISNUMBER(I33), ROUND(I33/$I$6*100, 2) & "%", "-") | K33: =IF(ISNUMBER(I33), RANK(I33, $I$7:$I$40), "-") | L33: เข้าสอบ | M33: S__8118305_0.jpg
A34: 28 | B34: ห้อง 2 | C34: 10 | D34: 69219090029 | E34: 029 | F34: นายภูธเรศ อินทโชติ | G34: 18 | H34: 13 | I34: =IF(COUNT(G34:H34)>0, SUM(G34:H34), "-") | J34: =IF(ISNUMBER(I34), ROUND(I34/$I$6*100, 2) & "%", "-") | K34: =IF(ISNUMBER(I34), RANK(I34, $I$7:$I$40), "-") | L34: เข้าสอบ | M34: S__8118306_0.jpg
A35: 29 | B35: ห้อง 2 | C35: 11 | D35: 69219090030 | E35: 030 | F35: เด็กหญิงวราภรณ์ มั่นคง | G35: 12 | H35: 0 | I35: =IF(COUNT(G35:H35)>0, SUM(G35:H35), "-") | J35: =IF(ISNUMBER(I35), ROUND(I35/$I$6*100, 2) & "%", "-") | K35: =IF(ISNUMBER(I35), RANK(I35, $I$7:$I$40), "-") | L35: เข้าสอบ | M35: S__8118307_0.jpg
A36: 30 | B36: ห้อง 2 | C36: 12 | D36: 69219090031 | E36: 031 | F36: นายวีรวัฒน์ วงษ์ทิพย์ | G36: 13 | H36: 0 | I36: =IF(COUNT(G36:H36)>0, SUM(G36:H36), "-") | J36: =IF(ISNUMBER(I36), ROUND(I36/$I$6*100, 2) & "%", "-") | K36: =IF(ISNUMBER(I36), RANK(I36, $I$7:$I$40), "-") | L36: เข้าสอบ | M36: S__8118295_0.jpg
A37: 31 | B37: ห้อง 2 | C37: 13 | D37: 69219090032 | E37: 032 | F37: นายวุฒิกร พาณิชย์กุลเกียรติ | G37: 12 | H37: 2 | I37: =IF(COUNT(G37:H37)>0, SUM(G37:H37), "-") | J37: =IF(ISNUMBER(I37), ROUND(I37/$I$6*100, 2) & "%", "-") | K37: =IF(ISNUMBER(I37), RANK(I37, $I$7:$I$40), "-") | L37: เข้าสอบ | M37: S__8118308_0.jpg
A38: 32 | B38: ห้อง 2 | C38: 14 | D38: 69219090033 | E38: 033 | F38: เด็กหญิงสโรชา มาเส็ง | G38: 11 | H38: 0 | I38: =IF(COUNT(G38:H38)>0, SUM(G38:H38), "-") | J38: =IF(ISNUMBER(I38), ROUND(I38/$I$6*100, 2) & "%", "-") | K38: =IF(ISNUMBER(I38), RANK(I38, $I$7:$I$40), "-") | L38: เข้าสอบ | M38: S__8118299_0.jpg
A39: 33 | B39: ห้อง 2 | C39: 15 | D39: 69219090034 | E39: 034 | F39: นายอธิป ทองดอนเถื่อน | G39: 21 | H39: 8 | I39: =IF(COUNT(G39:H39)>0, SUM(G39:H39), "-") | J39: =IF(ISNUMBER(I39), ROUND(I39/$I$6*100, 2) & "%", "-") | K39: =IF(ISNUMBER(I39), RANK(I39, $I$7:$I$40), "-") | L39: เข้าสอบ | M39: S__8118302_0.jpg
A40: 34 | B40: ห้อง 2 | C40: 16 | D40: 69219090035 | E40: 035 | F40: เด็กหญิงอารยา จันทน | G40: 19 | H40: 8 | I40: =IF(COUNT(G40:H40)>0, SUM(G40:H40), "-") | J40: =IF(ISNUMBER(I40), ROUND(I40/$I$6*100, 2) & "%", "-") | K40: =IF(ISNUMBER(I40), RANK(I40, $I$7:$I$40), "-") | L40: เข้าสอบ | M40: S__8118303_0.jpg
F41: คะแนนเฉลี่ย (Average) | G41: =IFERROR(ROUND(AVERAGE(G7:G40), 2), "-") | H41: =IFERROR(ROUND(AVERAGE(H7:H40), 2), "-") | I41: =IFERROR(ROUND(AVERAGE(I7:I40), 2), "-") | J41: =IFERROR(ROUND(AVERAGE(I7:I40)/50*100, 2) & "%", "-")
...

Sheet คะแนนเก็บแบบฝึกหัด (34 คน)
A1: 📝 แบบบันทึกคะแนนเก็บแบบฝึกหัดและชิ้นงาน (เรียงลำดับตามหลักสูตร) - รวมทั้ง 2 ห้อง (34 คน)
A2: วิชา 21909-1006 พื้นฐานการสร้างเว็บไซต์ | แบบฝึกหัดที่ 1 - 8 + โปรเจค Figma + งานกลุ่ม | เต็ม 100 คะแนน
A4: ลำดับรวม | B4: ห้อง | C4: เลขที่ | D4: รหัส | E4: ชื่อ - นามสกุล | F4: แบบฝึกหัดที่ 1 แนะนำตัวเอง (10) | G4: แบบฝึกหัดที่ 2 ใบงาน (10) | H4: แบบฝึกหัดที่ 3 CSS 3 รูปแบบ (10) | I4: แบบฝึกหัดที่ 4 colspan+rowspan (10) | J4: แบบฝึกหัดที่ 5 Form/Boxmodel (10) | K4: แบบฝึกหัดที่ 6 Boxmodel/Form (10) | L4: แบบฝึกหัดที่ 7 Flexbox Layout (10) | M4: แบบฝึกหัดที่ 8 Grid Layout (10) | N4: โปรเจคเว็บ Figma (10) | O4: งานกลุ่ม (10) | P4: รวมคะแนนเก็บ (เต็ม 100) | Q4: ร้อยละ (%) | R4: ลำดับที่ (Rank)
E5: คะแนนเต็ม | F5: 10 | G5: 10 | H5: 10 | I5: 10 | J5: 10 | K5: 10 | L5: 10 | M5: 10 | N5: 10 | O5: 10 | P5: 100 | Q5: 100.0% | R5: -
A6: 1 | B6: ห้อง 1 | C6: 1 | D6: 001 | E6: นายกฤศมน บุญเปี่ยม | F6: 7 | G6: 9 | I6: 10 | K6: 10 | L6: 10 | M6: 10 | N6: 10 | P6: =IF(COUNT(F6:O6)>0, SUM(F6:O6), "-") | Q6: =IF(ISNUMBER(P6), ROUND(P6/$P$5*100, 1) & "%", "-") | R6: =IF(ISNUMBER(P6), RANK(P6, $P$6:$P$39), "-")
A7: 2 | B7: ห้อง 1 | C7: 2 | D7: 002 | E7: เด็กชายกษธณชล การรักเรียน | F7: 8 | G7: 10 | I7: 10 | K7: 10 | M7: 10 | N7: 10 | P7: =IF(COUNT(F7:O7)>0, SUM(F7:O7), "-") | Q7: =IF(ISNUMBER(P7), ROUND(P7/$P$5*100, 1) & "%", "-") | R7: =IF(ISNUMBER(P7), RANK(P7, $P$6:$P$39), "-")
A8: 3 | B8: ห้อง 1 | C8: 3 | D8: 003 | E8: นางสาวกัญญ์วรา ทองดี | F8: 8 | G8: 9 | H8: 10 | I8: 10 | J8: 10 | K8: 10 | L8: 10 | M8: 10 | N8: 10 | P8: =IF(COUNT(F8:O8)>0, SUM(F8:O8), "-") | Q8: =IF(ISNUMBER(P8), ROUND(P8/$P$5*100, 1) & "%", "-") | R8: =IF(ISNUMBER(P8), RANK(P8, $P$6:$P$39), "-")
A9: 4 | B9: ห้อง 1 | C9: 4 | D9: 004 | E9: นายกันธรักษ์ พานทอง | F9: 7 | G9: 10 | H9: 10 | I9: 10 | J9: 10 | K9: 10 | L9: 10 | M9: 10 | N9: 10 | P9: =IF(COUNT(F9:O9)>0, SUM(F9:O9), "-") | Q9: =IF(ISNUMBER(P9), ROUND(P9/$P$5*100, 1) & "%", "-") | R9: =IF(ISNUMBER(P9), RANK(P9, $P$6:$P$39), "-")
A10: 5 | B10: ห้อง 1 | C10: 5 | D10: 005 | E10: เด็กชายคุณานนต์ พิมพ์จันทร์ | F10: 7 | G10: 10 | H10: 10 | I10: 10 | J10: 10 | K10: 10 | M10: 10 | N10: 10 | P10: =IF(COUNT(F10:O10)>0, SUM(F10:O10), "-") | Q10: =IF(ISNUMBER(P10), ROUND(P10/$P$5*100, 1) & "%", "-") | R10: =IF(ISNUMBER(P10), RANK(P10, $P$6:$P$39), "-")
A11: 6 | B11: ห้อง 1 | C11: 6 | D11: 006 | E11: เด็กชายเฉลิมวงศ์ มะลิใย | F11: 9 | G11: 9 | I11: 10 | J11: 10 | K11: 10 | L11: 10 | N11: 10 | P11: =IF(COUNT(F11:O11)>0, SUM(F11:O11), "-") | Q11: =IF(ISNUMBER(P11), ROUND(P11/$P$5*100, 1) & "%", "-") | R11: =IF(ISNUMBER(P11), RANK(P11, $P$6:$P$39), "-")
A12: 7 | B12: ห้อง 1 | C12: 7 | D12: 007 | E12: นางสาวชลดา เรือนแก้ว | F12: 6 | G12: 9 | I12: 10 | L12: 10 | P12: =IF(COUNT(F12:O12)>0, SUM(F12:O12), "-") | Q12: =IF(ISNUMBER(P12), ROUND(P12/$P$5*100, 1) & "%", "-") | R12: =IF(ISNUMBER(P12), RANK(P12, $P$6:$P$39), "-")
A13: 8 | B13: ห้อง 1 | C13: 8 | D13: 008 | E13: นายณัฐกรณ์ กองทอง | F13: 5 | G13: 8 | H13: 10 | I13: 10 | J13: 10 | P13: =IF(COUNT(F13:O13)>0, SUM(F13:O13), "-") | Q13: =IF(ISNUMBER(P13), ROUND(P13/$P$5*100, 1) & "%", "-") | R13: =IF(ISNUMBER(P13), RANK(P13, $P$6:$P$39), "-")
A14: 9 | B14: ห้อง 1 | C14: 9 | D14: 009 | E14: นายณัฐพล ทวีทรัพย์ | F14: 7 | G14: 9 | H14: 10 | I14: 10 | J14: 10 | K14: 10 | L14: 10 | N14: 10 | P14: =IF(COUNT(F14:O14)>0, SUM(F14:O14), "-") | Q14: =IF(ISNUMBER(P14), ROUND(P14/$P$5*100, 1) & "%", "-") | R14: =IF(ISNUMBER(P14), RANK(P14, $P$6:$P$39), "-")
A15: 10 | B15: ห้อง 1 | C15: 10 | D15: 010 | E15: นายต้นตระการ เพชรภู่ | F15: 8 | G15: 7 | H15: 10 | K15: 10 | M15: 10 | N15: 10 | P15: =IF(COUNT(F15:O15)>0, SUM(F15:O15), "-") | Q15: =IF(ISNUMBER(P15), ROUND(P15/$P$5*100, 1) & "%", "-") | R15: =IF(ISNUMBER(P15), RANK(P15, $P$6:$P$39), "-")
A16: 11 | B16: ห้อง 1 | C16: 11 | D16: 011 | E16: นายตฤณ ตาดทอง | F16: 9 | G16: 9 | H16: 10 | I16: 10 | J16: 10 | K16: 10 | L16: 10 | M16: 10 | N16: 10 | P16: =IF(COUNT(F16:O16)>0, SUM(F16:O16), "-") | Q16: =IF(ISNUMBER(P16), ROUND(P16/$P$5*100, 1) & "%", "-") | R16: =IF(ISNUMBER(P16), RANK(P16, $P$6:$P$39), "-")
A17: 12 | B17: ห้อง 1 | C17: 12 | D17: 012 | E17: นายธนพัฒน์ บุญเรือง | F17: 8 | G17: 9 | H17: 10 | I17: 10 | J17: 10 | K17: 10 | L17: 10 | M17: 10 | N17: 10 | P17: =IF(COUNT(F17:O17)>0, SUM(F17:O17), "-") | Q17: =IF(ISNUMBER(P17), ROUND(P17/$P$5*100, 1) & "%", "-") | R17: =IF(ISNUMBER(P17), RANK(P17, $P$6:$P$39), "-")
A18: 13 | B18: ห้อง 1 | C18: 13 | D18: 013 | E18: นายธีรภัทร วาสิทธิ์เทพ | F18: 8 | G18: 10 | H18: 10 | I18: 10 | J18: 10 | K18: 10 | L18: 10 | N18: 10 | P18: =IF(COUNT(F18:O18)>0, SUM(F18:O18), "-") | Q18: =IF(ISNUMBER(P18), ROUND(P18/$P$5*100, 1) & "%", "-") | R18: =IF(ISNUMBER(P18), RANK(P18, $P$6:$P$39), "-")
A19: 14 | B19: ห้อง 1 | C19: 14 | D19: 014 | E19: นายภูเบต ควันทอง | G19: 9 | P19: =IF(COUNT(F19:O19)>0, SUM(F19:O19), "-") | Q19: =IF(ISNUMBER(P19), ROUND(P19/$P$5*100, 1) & "%", "-") | R19: =IF(ISNUMBER(P19), RANK(P19, $P$6:$P$39), "-")
A20: 15 | B20: ห้อง 1 | C20: 15 | D20: 015 | E20: นายภูวพิศิษฐ์ ใหลสกุล | F20: 7 | G20: 8 | H20: 10 | I20: 10 | J20: 10 | K20: 10 | L20: 10 | M20: 10 | N20: 10 | P20: =IF(COUNT(F20:O20)>0, SUM(F20:O20), "-") | Q20: =IF(ISNUMBER(P20), ROUND(P20/$P$5*100, 1) & "%", "-") | R20: =IF(ISNUMBER(P20), RANK(P20, $P$6:$P$39), "-")
A21: 16 | B21: ห้อง 1 | C21: 16 | D21: 016 | E21: นางสาวมินตา บินอามัด | F21: 8 | G21: 9 | H21: 10 | I21: 10 | J21: 10 | K21: 10 | L21: 10 | M21: 10 | N21: 10 | P21: =IF(COUNT(F21:O21)>0, SUM(F21:O21), "-") | Q21: =IF(ISNUMBER(P21), ROUND(P21/$P$5*100, 1) & "%", "-") | R21: =IF(ISNUMBER(P21), RANK(P21, $P$6:$P$39), "-")
A22: 17 | B22: ห้อง 1 | C22: 17 | D22: 017 | E22: นายอัรฮัม ยูนุ | F22: 9 | G22: 10 | H22: 10 | I22: 10 | J22: 10 | K22: 10 | L22: 10 | M22: 10 | N22: 10 | P22: =IF(COUNT(F22:O22)>0, SUM(F22:O22), "-") | Q22: =IF(ISNUMBER(P22), ROUND(P22/$P$5*100, 1) & "%", "-") | R22: =IF(ISNUMBER(P22), RANK(P22, $P$6:$P$39), "-")
A23: 18 | B23: ห้อง 1 | C23: 18 | D23: 018 | E23: นายอานนท์ณัฏฐ์ ไวพจน์ | F23: 5 | G23: 9 | H23: 10 | I23: 10 | J23: 10 | K23: 10 | L23: 10 | M23: 10 | N23: 10 | P23: =IF(COUNT(F23:O23)>0, SUM(F23:O23), "-") | Q23: =IF(ISNUMBER(P23), ROUND(P23/$P$5*100, 1) & "%", "-") | R23: =IF(ISNUMBER(P23), RANK(P23, $P$6:$P$39), "-")
A24: 19 | B24: ห้อง 2 | C24: 1 | D24: 020 | E24: นายชุติวัต สุขมั่น | F24: 9 | G24: 9 | H24: 10 | I24: 10 | J24: 10 | K24: 10 | L24: 10 | M24: 10 | P24: =IF(COUNT(F24:O24)>0, SUM(F24:O24), "-") | Q24: =IF(ISNUMBER(P24), ROUND(P24/$P$5*100, 1) & "%", "-") | R24: =IF(ISNUMBER(P24), RANK(P24, $P$6:$P$39), "-")
A25: 20 | B25: ห้อง 2 | C25: 2 | D25: 021 | E25: เด็กชายณัพร รัตนสุวรรณ | F25: 9 | G25: 9 | H25: 10 | J25: 10 | P25: =IF(COUNT(F25:O25)>0, SUM(F25:O25), "-") | Q25: =IF(ISNUMBER(P25), ROUND(P25/$P$5*100, 1) & "%", "-") | R25: =IF(ISNUMBER(P25), RANK(P25, $P$6:$P$39), "-")
A26: 21 | B26: ห้อง 2 | C26: 3 | D26: 022 | E26: นายตุลยวัต ทาสีทอง | F26: 8 | G26: 0 | H26: 10 | I26: 10 | J26: 10 | L26: 5 | M26: 10 | P26: =IF(COUNT(F26:O26)>0, SUM(F26:O26), "-") | Q26: =IF(ISNUMBER(P26), ROUND(P26/$P$5*100, 1) & "%", "-") | R26: =IF(ISNUMBER(P26), RANK(P26, $P$6:$P$39), "-")
A27: 22 | B27: ห้อง 2 | C27: 4 | D27: 023 | E27: เด็กชายธนกฤต แก้วตา | F27: 8 | G27: 8 | H27: 10 | I27: 10 | J27: 10 | L27: 10 | M27: 10 | N27: 10 | P27: =IF(COUNT(F27:O27)>0, SUM(F27:O27), "-") | Q27: =IF(ISNUMBER(P27), ROUND(P27/$P$5*100, 1) & "%", "-") | R27: =IF(ISNUMBER(P27), RANK(P27, $P$6:$P$39), "-")
A28: 23 | B28: ห้อง 2 | C28: 5 | D28: 024 | E28: นายธเนศพล กันเมือง | F28: 7 | G28: 8 | H28: 10 | I28: 10 | J28: 10 | L28: 5 | M28: 10 | P28: =IF(COUNT(F28:O28)>0, SUM(F28:O28), "-") | Q28: =IF(ISNUMBER(P28), ROUND(P28/$P$5*100, 1) & "%", "-") | R28: =IF(ISNUMBER(P28), RANK(P28, $P$6:$P$39), "-")
A29: 24 | B29: ห้อง 2 | C29: 6 | D29: 025 | E29: นายนรากร จันทร์กล่ำ | F29: 9 | G29: 0 | H29: 10 | I29: 10 | P29: =IF(COUNT(F29:O29)>0, SUM(F29:O29), "-") | Q29: =IF(ISNUMBER(P29), ROUND(P29/$P$5*100, 1) & "%", "-") | R29: =IF(ISNUMBER(P29), RANK(P29, $P$6:$P$39), "-")
A30: 25 | B30: ห้อง 2 | C30: 7 | D30: 026 | E30: นายนราวิชญ์ ทองระคนธ์ | F30: 8 | G30: 8 | H30: 10 | J30: 10 | K30: 10 | L30: 10 | P30: =IF(COUNT(F30:O30)>0, SUM(F30:O30), "-") | Q30: =IF(ISNUMBER(P30), ROUND(P30/$P$5*100, 1) & "%", "-") | R30: =IF(ISNUMBER(P30), RANK(P30, $P$6:$P$39), "-")
A31: 26 | B31: ห้อง 2 | C31: 8 | D31: 027 | E31: นายนันทพงศ์ ช่ออุบล | F31: 5 | J31: 10 | P31: =IF(COUNT(F31:O31)>0, SUM(F31:O31), "-") | Q31: =IF(ISNUMBER(P31), ROUND(P31/$P$5*100, 1) & "%", "-") | R31: =IF(ISNUMBER(P31), RANK(P31, $P$6:$P$39), "-")
A32: 27 | B32: ห้อง 2 | C32: 9 | D32: 028 | E32: เด็กชายพงศ์พัทธ์ โสดา | F32: 9 | G32: 8 | H32: 10 | I32: 10 | J32: 10 | K32: 10 | L32: 5 | N32: 10 | P32: =IF(COUNT(F32:O32)>0, SUM(F32:O32), "-") | Q32: =IF(ISNUMBER(P32), ROUND(P32/$P$5*100, 1) & "%", "-") | R32: =IF(ISNUMBER(P32), RANK(P32, $P$6:$P$39), "-")
A33: 28 | B33: ห้อง 2 | C33: 10 | D33: 029 | E33: นายภูธเรศ อินทโชติ | F33: 8 | G33: 9 | H33: 10 | I33: 10 | J33: 10 | K33: 10 | L33: 10 | M33: 10 | N33: 10 | P33: =IF(COUNT(F33:O33)>0, SUM(F33:O33), "-") | Q33: =IF(ISNUMBER(P33), ROUND(P33/$P$5*100, 1) & "%", "-") | R33: =IF(ISNUMBER(P33), RANK(P33, $P$6:$P$39), "-")
A34: 29 | B34: ห้อง 2 | C34: 11 | D34: 030 | E34: เด็กหญิงวราภรณ์ มั่นคง | F34: 8 | G34: 8 | H34: 10 | J34: 10 | L34: 10 | M34: 10 | N34: 10 | P34: =IF(COUNT(F34:O34)>0, SUM(F34:O34), "-") | Q34: =IF(ISNUMBER(P34), ROUND(P34/$P$5*100, 1) & "%", "-") | R34: =IF(ISNUMBER(P34), RANK(P34, $P$6:$P$39), "-")
A35: 30 | B35: ห้อง 2 | C35: 12 | D35: 031 | E35: นายวีรวัฒน์ วงษ์ทิพย์ | F35: 9 | G35: 9 | I35: 10 | J35: 10 | P35: =IF(COUNT(F35:O35)>0, SUM(F35:O35), "-") | Q35: =IF(ISNUMBER(P35), ROUND(P35/$P$5*100, 1) & "%", "-") | R35: =IF(ISNUMBER(P35), RANK(P35, $P$6:$P$39), "-")
A36: 31 | B36: ห้อง 2 | C36: 13 | D36: 032 | E36: นายวุฒิกร พาณิชย์กุลเกียรติ | F36: 5 | G36: 7 | H36: 10 | I36: 10 | J36: 10 | K36: 10 | L36: 10 | M36: 10 | N36: 10 | P36: =IF(COUNT(F36:O36)>0, SUM(F36:O36), "-") | Q36: =IF(ISNUMBER(P36), ROUND(P36/$P$5*100, 1) & "%", "-") | R36: =IF(ISNUMBER(P36), RANK(P36, $P$6:$P$39), "-")
A37: 32 | B37: ห้อง 2 | C37: 14 | D37: 033 | E37: เด็กหญิงสโรชา มาเส็ง | F37: 8 | G37: 9 | I37: 10 | J37: 10 | P37: =IF(COUNT(F37:O37)>0, SUM(F37:O37), "-") | Q37: =IF(ISNUMBER(P37), ROUND(P37/$P$5*100, 1) & "%", "-") | R37: =IF(ISNUMBER(P37), RANK(P37, $P$6:$P$39), "-")
A38: 33 | B38: ห้อง 2 | C38: 15 | D38: 034 | E38: นายอธิป ทองดอนเถื่อน | F38: 8 | G38: 9 | H38: 10 | I38: 10 | J38: 10 | P38: =IF(COUNT(F38:O38)>0, SUM(F38:O38), "-") | Q38: =IF(ISNUMBER(P38), ROUND(P38/$P$5*100, 1) & "%", "-") | R38: =IF(ISNUMBER(P38), RANK(P38, $P$6:$P$39), "-")
A39: 34 | B39: ห้อง 2 | C39: 16 | D39: 035 | E39: เด็กหญิงอารยา จันทน | F39: 10 | G39: 8 | H39: 10 | I39: 10 | J39: 10 | K39: 10 | L39: 10 | N39: 10 | P39: =IF(COUNT(F39:O39)>0, SUM(F39:O39), "-") | Q39: =IF(ISNUMBER(P39), ROUND(P39/$P$5*100, 1) & "%", "-") | R39: =IF(ISNUMBER(P39), RANK(P39, $P$6:$P$39), "-")
A40: คะแนนเฉลี่ย (Average) | F40: =IFERROR(ROUND(AVERAGE(F6:F39), 2), "-") | G40: =IFERROR(ROUND(AVERAGE(G6:G39), 2), "-") | H40: =IFERROR(ROUND(AVERAGE(H6:H39), 2), "-") | I40: =IFERROR(ROUND(AVERAGE(I6:I39), 2), "-") | J40: =IFERROR(ROUND(AVERAGE(J6:J39), 2), "-") | K40: =IFERROR(ROUND(AVERAGE(K6:K39), 2), "-") | L40: =IFERROR(ROUND(AVERAGE(L6:L39), 2), "-") | M40: =IFERROR(ROUND(AVERAGE(M6:M39), 2), "-") | ... P40: =IFERROR(ROUND(AVERAGE(P6:P39), 2), "-")
A41: คะแนนสูงสุด (Max) | F41: =IFERROR(MAX(F6:F39), "-") | G41: =IFERROR(MAX(G6:G39), "-") | H41: =IFERROR(MAX(H6:H39), "-") | I41: =IFERROR(MAX(I6:I39), "-") | J41: =IFERROR(MAX(J6:J39), "-") | K41: =IFERROR(MAX(K6:K39), "-") | L41: =IFERROR(MAX(L6:L39), "-") | M41: =IFERROR(MAX(M6:M39), "-") | ... P41: =IFERROR(MAX(P6:P39), "-")
...

Sheet ห้อง 1 - ตรวจข้อสอบละเอียด
A1: 📝 รายละเอียดผลการตรวจข้อสอบรายข้อ - ห้อง 1 (18 คน)
A2: วิชา 21909-1006 พื้นฐานการสร้างเว็บไซต์ | ตอนที่ 1 แบบทดสอบปรนัย 30 ข้อ (ข้อละ 1 คะแนนเต็ม 30)
A4: ข้อมูลนักศึกษา | E4: ผลการตอบข้อสอบรายข้อ (ข้อ 1 - 30) [เฉลยกำกับด้านบน] | AI4: สรุปคะแนน
A5: เลขที่ | B5: รหัส | C5: ชื่อ - นามสกุล | D5: ไฟล์ภาพ | E5: ข.1 | F5: ข.2 | G5: ข.3 | H5: ข.4 | I5: ข.5 | J5: ข.6 | K5: ข.7 | L5: ข.8 | M5: ข.9 | N5: ข.10 | O5: ข.11 | P5: ข.12 | Q5: ข.13 | R5: ข.14 | S5: ข.15 | T5: ข.16 | U5: ข.17 | V5: ข.18 | W5: ข.19 | X5: ข.20 | Y5: ข.21 | Z5: ข.22 | AA5: ข.23 | AB5: ข.24 | AC5: ข.25 | AD5: ข.26 | AE5: ข.27 | AF5: ข.28 | AG5: ข.29 | AH5: ข.30 | AI5: รวม (30) | AJ5: ร้อยละ
A6: - | B6: KEY | C6: เฉลยคำตอบทางการ | D6: Rubric Key | E6: ข | F6: ก | G6: ค | H6: ง | I6: ข | J6: ก | K6: ค | L6: ข | M6: ง | N6: ก | O6: ค | P6: ข | Q6: ก | R6: ง | S6: ข | T6: ค | U6: ก | V6: ง | W6: ข | X6: ค | Y6: ก | Z6: ค | AA6: ง | AB6: ข | AC6: ก | AD6: ง | AE6: ค | AF6: ข | AG6: ง | AH6: ค | AI6: 30 | AJ6: 100.0%
A7: 1 | B7: 001 | C7: นายกฤศมน บุญเปี่ยม | D7: S__8118291_0.jpg | E7: ข | F7: ค | G7: ค | H7: ง | I7: ข | J7: ก | K7: ค | L7: ข | M7: ง | N7: ก | O7: ข | P7: ง | Q7: ก | R7: ง | S7: ข | T7: ค | U7: ก | V7: ค | W7: ข | X7: ค | Y7: ก | Z7: ก | AA7: ข | AB7: ก | AC7: ก | AD7: ง | AE7: ข | AF7: ข | AG7: ก | AH7: ง | AI7: 20 | AJ7: 66.67%
A8: 2 | B8: 002 | C8: เด็กชายกษธณชล การรักเรียน | D8: S__8118284_0.jpg | E8: ข | F8: ก | G8: ข | H8: ง | I8: ก | J8: ค | K8: ง | L8: ง | M8: ข | N8: ข | O8: ง | P8: ง | Q8: ข | R8: ค | S8: ข | T8: ค | U8: ก | V8: ง | W8: ข | X8: ค | Y8: ง | Z8: ง | AA8: ข | AB8: ข | AC8: ง | AD8: ก | AE8: ค | AF8: ข | AG8: ง | AH8: ค | AI8: 14 | AJ8: 46.67%
A9: 3 | B9: 003 | C9: นางสาวกัญญ์วรา ทองดี | D9: S__8118292_0.jpg | E9: ก | F9: ก | G9: ค | H9: ง | I9: ข | J9: ก | K9: ค | L9: ข | M9: ง | N9: ก | O9: ค | P9: ข | Q9: ก | R9: ง | S9: ข | T9: ค | U9: ก | V9: ง | W9: ข | X9: ค | Y9: ก | Z9: ค | AA9: ง | AB9: ข | AC9: ค | AD9: ง | AE9: ก | AF9: ข | AG9: ข | AH9: ค | AI9: 26 | AJ9: 86.67%
A10: 4 | B10: 004 | C10: นายกันธรักษ์ พานทอง | D10: S__8118288_0.jpg | E10: ข | F10: ค | G10: ค | H10: ง | I10: ข | J10: ก | K10: ง | L10: ค | M10: ง | N10: ก | O10: ค | P10: ก | Q10: ก | R10: ง | S10: ข | T10: ค | U10: ก | V10: ก | W10: ข | X10: ค | Y10: ก | Z10: ค | AA10: ก | AB10: ก | AC10: ง | AD10: ง | AE10: ง | AF10: ก | AG10: ค | AH10: ข | AI10: 18 | AJ10: 60.00%
A11: 5 | B11: 005 | C11: เด็กชายคุณานนต์ พิมพ์จันทร์ | D11: S__8118286_0.jpg | E11: ข | F11: ก | G11: ค | H11: ง | I11: ข | J11: ก | K11: ก | L11: ข | M11: ก | N11: ก | O11: ค | P11: ข | Q11: ก | R11: ง | S11: ข | T11: ค | U11: ก | V11: ง | W11: ข | X11: ค | Y11: ก | Z11: ค | AA11: ง | AB11: ข | AC11: ก | AD11: ง | AE11: ค | AF11: ข | AG11: ก | AH11: ค | AI11: 27 | AJ11: 90.00%
A12: 6 | B12: 006 | C12: เด็กชายเฉลิมวงศ์ มะลิใย | D12: S__8118280_0.jpg | E12: ข | F12: ก | G12: ข | H12: ง | I12: ก | J12: ก | K12: ค | L12: ข | M12: ง | N12: ก | O12: ค | P12: ง | Q12: ง | R12: ค | S12: ข | T12: ค | U12: ก | V12: ง | W12: ข | X12: ค | Y12: ก | Z12: ค | AA12: ง | AB12: ก | AC12: ก | AD12: ข | AE12: ก | AF12: ข | AG12: ง | AH12: ค | AI12: 22 | AJ12: 73.33%
A13: 7 | B13: 007 | C13: นางสาวชลดา เรือนแก้ว | D13: S__8118285_0.jpg | E13: ข | F13: ง | G13: ข | H13: ก | I13: ข | J13: ก | K13: ค | L13: ข | M13: ค | N13: ก | O13: ง | P13: ง | Q13: ค | R13: ค | S13: ข | T13: ค | U13: ก | V13: ก | W13: ข | X13: ค | Y13: ก | Z13: ก | AA13: ข | AB13: ง | AC13: ง | AD13: ง | AE13: ค | AF13: ก | AG13: ง | AH13: ข | AI13: 15 | AJ13: 50.00%
A14: 8 | B14: 008 | C14: นายณัฐกรณ์ กองทอง | D14: ขาดสอบ | E14: - | F14: - | G14: - | H14: - | I14: - | J14: - | K14: - | L14: - | M14: - | N14: - | O14: - | P14: - | Q14: - | R14: - | S14: - | T14: - | U14: - | V14: - | W14: - | X14: - | Y14: - | Z14: - | AA14: - | AB14: - | AC14: - | AD14: - | AE14: - | AF14: - | AG14: - | AH14: - | AI14: - | AJ14: -
A15: 9 | B15: 009 | C15: นายณัฐพล ทวีทรัพย์ | D15: S__8118289_0.jpg | E15: ง | F15: ข | G15: ค | H15: ง | I15: ข | J15: ก | K15: ก | L15: ข | M15: ง | N15: ก | O15: ก | P15: ง | Q15: ก | R15: ง | S15: ก | T15: ค | U15: ก | V15: ง | W15: ข | X15: ค | Y15: ก | Z15: ข | AA15: ก | AB15: ค | AC15: ก | AD15: ง | AE15: ก | AF15: ก | AG15: ก | AH15: ก | AI15: 17 | AJ15: 56.67%
A16: 10 | B16: 010 | C16: นายต้นตระการ เพชรภู่ | D16: S__8118281_0.jpg | E16: ข | F16: ค | G16: ก | H16: ง | I16: ค | J16: ข | K16: ก | L16: ก | M16: ค | N16: ก | O16: ข | P16: ค | Q16: ก | R16: ข | S16: ข | T16: ก | U16: ข | V16: ก | W16: ค | X16: ข | Y16: ง | Z16: ข | AA16: ก | AB16: ค | AC16: ข | AD16: ง | AE16: ข | AF16: ก | AG16: ค | AH16: ข | AI16: 6 | AJ16: 20.00%
A17: 11 | B17: 011 | C17: นายตฤณ ตาดทอง | D17: S__8118278_0.jpg | E17: ง | F17: ก | G17: ค | H17: ง | I17: ข | J17: ก | K17: ข | L17: ข | M17: ง | N17: ก | O17: ข | P17: ข | Q17: ก | R17: ง | S17: ข | T17: ค | U17: ก | V17: ง | W17: ข | X17: ค | Y17: ก | Z17: ค | AA17: ง | AB17: ข | AC17: ก | AD17: ง | AE17: ค | AF17: ข | AG17: ก | AH17: ง | AI17: 25 | AJ17: 83.33%
A18: 12 | B18: 012 | C18: นายธนพัฒน์ บุญเรือง | D18: S__8118283_0.jpg | E18: ข | F18: ค | G18: ค | H18: ง | I18: ข | J18: ก | K18: ง | L18: ข | M18: ง | N18: ข | O18: ค | P18: ข | Q18: ก | R18: ง | S18: ข | T18: ค | U18: ก | V18: ง | W18: ค | X18: ค | Y18: ข | Z18: ก | AA18: ง | AB18: ข | AC18: ก | AD18: ง | AE18: ข | AF18: ข | AG18: ข | AH18: ค | AI18: 22 | AJ18: 73.33%
A19: 13 | B19: 013 | C19: นายธีรภัทร วาสิทธิ์เทพ | D19: S__8118282_0.jpg | E19: ค | F19: ข | G19: ค | H19: ง | I19: ข | J19: ง | K19: ง | L19: ก | M19: ข | N19: ก | O19: ค | P19: ก | Q19: ก | R19: ง | S19: ข | T19: ค | U19: ก | V19: ง | W19: ข | X19: ค | Y19: ก | Z19: ข | AA19: ง | AB19: ข | AC19: ข | AD19: ก | AE19: ข | AF19: ค | AG19: ข | AH19: ค | AI19: 17 | AJ19: 56.67%
A20: 14 | B20: 014 | C20: นายภูเบต ควันทอง | D20: ขาดสอบ | E20: - | F20: - | G20: - | H20: - | I20: - | J20: - | K20: - | L20: - | M20: - | N20: - | O20: - | P20: - | Q20: - | R20: - | S20: - | T20: - | U20: - | V20: - | W20: - | X20: - | Y20: - | Z20: - | AA20: - | AB20: - | AC20: - | AD20: - | AE20: - | AF20: - | AG20: - | AH20: - | AI20: - | AJ20: -
A21: 15 | B21: 015 | C21: นายภูวพิศิษฐ์ ใหลสกุล | D21: S__8118290_0.jpg | E21: ข | F21: ก | G21: ค | H21: ง | I21: ข | J21: ก | K21: ค | L21: ข | M21: ง | N21: ก | O21: ค | P21: ค | Q21: ก | R21: ก | S21: ข | T21: ค | U21: ก | V21: ง | W21: ข | X21: ง | Y21: ก | Z21: ค | AA21: ง | AB21: ข | AC21: ก | AD21: ง | AE21: ก | AF21: ข | AG21: ง | AH21: ค | AI21: 26 | AJ21: 86.67%
A22: 16 | B22: 016 | C22: นางสาวมินตา บินอามัด | D22: S__8118293_0.jpg | E22: ข | F22: ค | G22: ค | H22: ข | I22: ข | J22: ก | K22: ค | L22: ง | M22: ก | N22: ข | O22: ข | P22: ค | Q22: ข | R22: ง | S22: ข | T22: ค | U22: ก | V22: ข | W22: ค | X22: ค | Y22: ข | Z22: ก | AA22: ข | AB22: ค | AC22: ข | AD22: ก | AE22: ก | AF22: ก | AG22: ข | AH22: ก | AI22: 10 | AJ22: 33.33%
A23: 17 | B23: 017 | C23: นายอัรฮัม ยูนุ | D23: S__8118279_0.jpg | E23: ข | F23: ก | G23: ค | H23: ง | I23: ข | J23: ก | K23: ค | L23: ข | M23: ค | N23: ก | O23: ค | P23: ง | Q23: ก | R23: ค | S23: ข | T23: ค | U23: ก | V23: ง | W23: ข | X23: ค | Y23: ก | Z23: ค | AA23: ง | AB23: ข | AC23: ก | AD23: ง | AE23: ค | AF23: ข | AG23: ง | AH23: ก | AI23: 26 | AJ23: 86.67%
A24: 18 | B24: 018 | C24: นายอานนท์ณัฏฐ์ ไวพจน์ | D24: S__8118277_0.jpg | E24: ง | F24: ค | G24: ค | H24: ข | I24: ข | J24: ก | K24: ค | L24: ค | M24: ก | N24: ก | O24: ค | P24: ข | Q24: ข | R24: ง | S24: ข | T24: ค | U24: ก | V24: ง | W24: ข | X24: ค | Y24: ก | Z24: ข | AA24: ง | AB24: ข | AC24: ก | AD24: ค | AE24: ก | AF24: ก | AG24: ข | AH24: ง | AI24: 18 | AJ24: 60.00%
A25: - | B25: - | C25: จำนวนคนตอบถูก (คน) | D25: - | E25: =COUNTIF(E7:E24, "ข") | F25: =COUNTIF(F7:F24, "ก") | G25: =COUNTIF(G7:G24, "ค") | H25: =COUNTIF(H7:H24, "ง") | I25: =COUNTIF(I7:I24, "ข") | J25: =COUNTIF(J7:J24, "ก") | K25: =COUNTIF(K7:K24, "ค") | L25: =COUNTIF(L7:L24, "ข") | M25: =COUNTIF(M7:M24, "ง") | N25: =COUNTIF(N7:N24, "ก") | O25: =COUNTIF(O7:O24, "ค") | P25: =COUNTIF(P7:P24, "ข") | Q25: =COUNTIF(Q7:Q24, "ก") | R25: =COUNTIF(R7:R24, "ง") | S25: =COUNTIF(S7:S24, "ข") | T25: =COUNTIF(T7:T24, "ค") | U25: =COUNTIF(U7:U24, "ก") | V25: =COUNTIF(V7:V24, "ง") | W25: =COUNTIF(W7:W24, "ข") | X25: =COUNTIF(X7:X24, "ค") | Y25: =COUNTIF(Y7:Y24, "ก") | Z25: =COUNTIF(Z7:Z24, "ค") | AA25: =COUNTIF(AA7:AA24, "ง") | AB25: =COUNTIF(AB7:AB24, "ข") | AC25: =COUNTIF(AC7:AC24, "ก") | AD25: =COUNTIF(AD7:AD24, "ง") | AE25: =COUNTIF(AE7:AE24, "ค") | AF25: =COUNTIF(AF7:AF24, "ข") | AG25: =COUNTIF(AG7:AG24, "ง") | AH25: =COUNTIF(AH7:AH24, "ค") | AI25: =ROUND(AVERAGE(AI7:AI24), 2) | AJ25: =ROUND(AVERAGE(AI7:AI24)/30*100, 2) & "%"

Sheet ห้อง 2 - ตรวจข้อสอบละเอียด
A1: 📝 รายละเอียดผลการตรวจข้อสอบรายข้อ - ห้อง 2 (16 คน)
A2: วิชา 21909-1006 พื้นฐานการสร้างเว็บไซต์ | ตอนที่ 1 แบบทดสอบปรนัย 30 ข้อ (ข้อละ 1 คะแนนเต็ม 30)
A4: ข้อมูลนักศึกษา | E4: ผลการตอบข้อสอบรายข้อ (ข้อ 1 - 30) [เฉลยกำกับด้านบน] | AI4: สรุปคะแนน
A5: เลขที่ | B5: รหัส | C5: ชื่อ - นามสกุล | D5: ไฟล์ภาพ | E5: ข.1 | F5: ข.2 | G5: ข.3 | H5: ข.4 | I5: ข.5 | J5: ข.6 | K5: ข.7 | L5: ข.8 | M5: ข.9 | N5: ข.10 | O5: ข.11 | P5: ข.12 | Q5: ข.13 | R5: ข.14 | S5: ข.15 | T5: ข.16 | U5: ข.17 | V5: ข.18 | W5: ข.19 | X5: ข.20 | Y5: ข.21 | Z5: ข.22 | AA5: ข.23 | AB5: ข.24 | AC5: ข.25 | AD5: ข.26 | AE5: ข.27 | AF5: ข.28 | AG5: ข.29 | AH5: ข.30 | AI5: รวม (30) | AJ5: ร้อยละ
A6: - | B6: KEY | C6: เฉลยคำตอบทางการ | D6: Rubric Key | E6: ข | F6: ก | G6: ค | H6: ง | I6: ข | J6: ก | K6: ค | L6: ข | M6: ง | N6: ก | O6: ค | P6: ข | Q6: ก | R6: ง | S6: ข | T6: ค | U6: ก | V6: ง | W6: ข | X6: ค | Y6: ก | Z6: ค | AA6: ง | AB6: ข | AC6: ก | AD6: ง | AE6: ค | AF6: ข | AG6: ง | AH6: ค | AI6: 30 | AJ6: 100.0%
A7: 1 | B7: 020 | C7: นายชุติวัต สุขมั่น | D7: S__8118296_0.jpg | E7: ข | F7: ก | G7: ง | H7: ง | I7: ก | J7: ก | K7: ข | L7: ค | M7: ง | N7: ก | O7: ง | P7: ก | Q7: ก | R7: ข | S7: ก | T7: ค | U7: ข | V7: ง | W7: ก | X7: ค | Y7: ก | Z7: ค | AA7: ข | AB7: ง | AC7: ก | AD7: ข | AE7: ค | AF7: ข | AG7: ข | AH7: ข | AI7: 15 | AJ7: 50.00%
A8: 2 | B8: 021 | C8: เด็กชายณัพร รัตนสุวรรณ | D8: S__8118300_0.jpg | E8: ก | F8: ก | G8: ค | H8: ง | I8: ก | J8: ค | K8: ค | L8: ข | M8: ข | N8: ข | O8: ค | P8: ค | Q8: ก | R8: ง | S8: ค | T8: ก | U8: ข | V8: ก | W8: ก | X8: ก | Y8: ง | Z8: ค | AA8: ง | AB8: ข | AC8: ค | AD8: ก | AE8: ก | AF8: ค | AG8: ค | AH8: ง | AI8: 11 | AJ8: 36.67%
A9: 3 | B9: 022 | C9: นายตุลยวัต ทาสีทอง | D9: S__8118304_0.jpg | E9: ก | F9: ค | G9: ก | H9: ข | I9: ข | J9: ก | K9: ข | L9: ข | M9: ง | N9: ก | O9: ค | P9: ข | Q9: ก | R9: ง | S9: ข | T9: ค | U9: ก | V9: ก | W9: ค | X9: ค | Y9: ก | Z9: ก | AA9: ง | AB9: ข | AC9: ก | AD9: ง | AE9: ก | AF9: ข | AG9: ค | AH9: ก | AI9: 19 | AJ9: 63.33%
A10: 4 | B10: 023 | C10: เด็กชายธนกฤต แก้วตา | D10: S__8118301_0.jpg | E10: ก | F10: ข | G10: ค | H10: ง | I10: ข | J10: ก | K10: ค | L10: ข | M10: ง | N10: ก | O10: ค | P10: ง | Q10: ก | R10: ง | S10: ข | T10: ค | U10: ก | V10: ข | W10: ข | X10: ค | Y10: ก | Z10: ก | AA10: ง | AB10: ค | AC10: ก | AD10: ง | AE10: ก | AF10: ข | AG10: ง | AH10: ง | AI10: 22 | AJ10: 73.33%
A11: 5 | B11: 024 | C11: นายธเนศพล กันเมือง | D11: S__8118294_0.jpg | E11: ก | F11: ค | G11: ค | H11: ก | I11: ข | J11: ก | K11: ง | L11: ข | M11: ง | N11: ก | O11: ค | P11: ง | Q11: ก | R11: ง | S11: ง | T11: ค | U11: ก | V11: ข | W11: ค | X11: ค | Y11: ง | Z11: ก | AA11: ง | AB11: ง | AC11: ข | AD11: ข | AE11: ค | AF11: ข | AG11: ก | AH11: ค | AI11: 16 | AJ11: 53.33%
A12: 6 | B12: 025 | C12: นายนรากร จันทร์กล่ำ | D12: ขาดสอบ | E12: - | F12: - | G12: - | H12: - | I12: - | J12: - | K12: - | L12: - | M12: - | N12: - | O12: - | P12: - | Q12: - | R12: - | S12: - | T12: - | U12: - | V12: - | W12: - | X12: - | Y12: - | Z12: - | AA12: - | AB12: - | AC12: - | AD12: - | AE12: - | AF12: - | AG12: - | AH12: - | AI12: - | AJ12: -
A13: 7 | B13: 026 | C13: นายนราวิชญ์ ทองระคนธ์ | D13: S__8118297_0.jpg | E13: ข | F13: ก | G13: ง | H13: ง | I13: ก | J13: ก | K13: ข | L13: ค | M13: ง | N13: ก | O13: ค | P13: ค | Q13: ง | R13: ง | S13: ข | T13: ค | U13: ก | V13: ง | W13: ค | X13: ค | Y13: ก | Z13: ค | AA13: ก | AB13: ข | AC13: ค | AD13: ง | AE13: ค | AF13: ก | AG13: ค | AH13: ค | AI13: 19 | AJ13: 63.33%
A14: 8 | B14: 027 | C14: นายนันทพงศ์ ช่ออุบล | D14: S__8118309.jpg | E14: ก | F14: ก | G14: ค | H14: ข | I14: ง | J14: ก | K14: ข | L14: ข | M14: ง | N14: ก | O14: ก | P14: ค | Q14: ง | R14: ก | S14: ข | T14: ง | U14: ก | V14: ก | W14: ค | X14: ข | Y14: ง | Z14: ก | AA14: ก | AB14: ค | AC14: ข | AD14: ข | AE14: ง | AF14: ก | AG14: ค | AH14: ข | AI14: 8 | AJ14: 26.67%
A15: 9 | B15: 028 | C15: เด็กชายพงศ์พัทธ์ โสดา | D15: S__8118305_0.jpg | E15: ข | F15: ก | G15: ค | H15: ง | I15: ข | J15: ก | K15: ค | L15: ข | M15: ง | N15: ข | O15: ค | P15: ก | Q15: ก | R15: ง | S15: ข | T15: ค | U15: ก | V15: ก | W15: ข | X15: ค | Y15: ง | Z15: ข | AA15: ก | AB15: ค | AC15: ก | AD15: ง | AE15: ก | AF15: ข | AG15: ง | AH15: ค | AI15: 22 | AJ15: 73.33%
A16: 10 | B16: 029 | C16: นายภูธเรศ อินทโชติ | D16: S__8118306_0.jpg | E16: ง | F16: ก | G16: ค | H16: ง | I16: ก | J16: ก | K16: ง | L16: ข | M16: ง | N16: ก | O16: ค | P16: ง | Q16: ก | R16: ง | S16: ข | T16: ค | U16: ก | V16: ข | W16: ก | X16: ค | Y16: ง | Z16: ง | AA16: ง | AB16: ค | AC16: ง | AD16: ง | AE16: ง | AF16: ข | AG16: ก | AH16: ค | AI16: 18 | AJ16: 60.00%
A17: 11 | B17: 030 | C17: เด็กหญิงวราภรณ์ มั่นคง | D17: S__8118307_0.jpg | E17: ก | F17: ข | G17: ค | H17: ง | I17: ข | J17: ก | K17: ง | L17: ข | M17: ค | N17: ง | O17: ง | P17: ก | Q17: ข | R17: ค | S17: ข | T17: ค | U17: ก | V17: ค | W17: ข | X17: ค | Y17: ก | Z17: ง | AA17: ข | AB17: ก | AC17: ง | AD17: ก | AE17: ก | AF17: ข | AG17: ค | AH17: ง | AI17: 12 | AJ17: 40.00%
A18: 12 | B18: 031 | C18: นายวีรวัฒน์ วงษ์ทิพย์ | D18: S__8118295_0.jpg | E18: ก | F18: ก | G18: ค | H18: ง | I18: ก | J18: ก | K18: ค | L18: ข | M18: ข | N18: ง | O18: ก | P18: ข | Q18: ก | R18: ก | S18: ค | T18: ค | U18: ง | V18: ข | W18: ค | X18: ค | Y18: ง | Z18: ง | AA18: ก | AB18: ข | AC18: ค | AD18: ง | AE18: ค | AF18: ก | AG18: ค | AH18: ข | AI18: 13 | AJ18: 43.33%
A19: 13 | B19: 032 | C19: นายวุฒิกร พาณิชย์กุลเกียรติ | D19: S__8118308_0.jpg | E19: ข | F19: ค | G19: ค | H19: ข | I19: ก | J19: ก | K19: ง | L19: ค | M19: ก | N19: ก | O19: ค | P19: ก | Q19: ก | R19: ข | S19: ข | T19: ง | U19: ง | V19: ข | W19: ข | X19: ก | Y19: ก | Z19: ค | AA19: ข | AB19: ค | AC19: ค | AD19: ง | AE19: ก | AF19: ข | AG19: ก | AH19: ง | AI19: 12 | AJ19: 40.00%
A20: 14 | B20: 033 | C20: เด็กหญิงสโรชา มาเส็ง | D20: S__8118299_0.jpg | E20: ก | F20: ค | G20: ค | H20: ข | I20: ข | J20: ง | K20: ง | L20: ข | M20: ค | N20: ก | O20: ง | P20: ข | Q20: ข | R20: ก | S20: ง | T20: ค | U20: ก | V20: ข | W20: ง | X20: ค | Y20: ก | Z20: ง | AA20: ข | AB20: ข | AC20: ก | AD20: ค | AE20: ข | AF20: ง | AG20: ก | AH20: ง | AI20: 11 | AJ20: 36.67%
A21: 15 | B21: 034 | C21: นายอธิป ทองดอนเถื่อน | D21: S__8118302_0.jpg | E21: ค | F21: ก | G21: ก | H21: ง | I21: ข | J21: ก | K21: ง | L21: ข | M21: ง | N21: ก | O21: ค | P21: ข | Q21: ข | R21: ง | S21: ข | T21: ค | U21: ก | V21: ง | W21: ก | X21: ค | Y21: ง | Z21: ค | AA21: ง | AB21: ค | AC21: ก | AD21: ง | AE21: ค | AF21: ก | AG21: ข | AH21: ค | AI21: 21 | AJ21: 70.00%
A22: 16 | B22: 035 | C22: เด็กหญิงอารยา จันทน | D22: S__8118303_0.jpg | E22: ก | F22: ข | G22: ค | H22: ง | I22: ข | J22: ค | K22: ข | L22: ข | M22: ง | N22: ก | O22: ค | P22: ค | Q22: ก | R22: ค | S22: ข | T22: ค | U22: ก | V22: ข | W22: ง | X22: ค | Y22: ก | Z22: ค | AA22: ง | AB22: ง | AC22: ก | AD22: ง | AE22: ง | AF22: ข | AG22: ก | AH22: ค | AI22: 19 | AJ22: 63.33%
A23: - | B23: - | C23: จำนวนคนตอบถูก (คน) | D23: - | E23: =COUNTIF(E7:E22, "ข") | F23: =COUNTIF(F7:F22, "ก") | G23: =COUNTIF(G7:G22, "ค") | H23: =COUNTIF(H7:H22, "ง") | I23: =COUNTIF(I7:I22, "ข") | J23: =COUNTIF(J7:J22, "ก") | K23: =COUNTIF(K7:K22, "ค") | L23: =COUNTIF(L7:L22, "ข") | M23: =COUNTIF(M7:M22, "ง") | N23: =COUNTIF(N7:N22, "ก") | O23: =COUNTIF(O7:O22, "ค") | P23: =COUNTIF(P7:P22, "ข") | Q23: =COUNTIF(Q7:Q22, "ก") | R23: =COUNTIF(R7:R22, "ง") | S23: =COUNTIF(S7:S22, "ข") | T23: =COUNTIF(T7:T22, "ค") | U23: =COUNTIF(U7:U22, "ก") | V23: =COUNTIF(V7:V22, "ง") | W23: =COUNTIF(W7:W22, "ข") | X23: =COUNTIF(X7:X22, "ค") | Y23: =COUNTIF(Y7:Y22, "ก") | Z23: =COUNTIF(Z7:Z22, "ค") | AA23: =COUNTIF(AA7:AA22, "ง") | AB23: =COUNTIF(AB7:AB22, "ข") | AC23: =COUNTIF(AC7:AC22, "ก") | AD23: =COUNTIF(AD7:AD22, "ง") | AE23: =COUNTIF(AE7:AE22, "ค") | AF23: =COUNTIF(AF7:AF22, "ข") | AG23: =COUNTIF(AG7:AG22, "ง") | AH23: =COUNTIF(AH7:AH22, "ค") | AI23: =ROUND(AVERAGE(AI7:AI22), 2) | AJ23: =ROUND(AVERAGE(AI7:AI22)/30*100, 2) & "%"

Sheet วิเคราะห์ข้อสอบ (Item Analysis)
A1: 🔬 รายงานการวิเคราะห์ข้อสอบรายข้อ (Item Difficulty & Distractor Analysis)
A2: วิชา 21909-1006 พื้นฐานการสร้างเว็บไซต์ | จำนวนผู้เข้าสอบ N = 31 คน | วิเคราะห์ดัชนีความยากง่าย (P-value)
A4: ข้อมูลข้อสอบ | D4: การกระจายตัวของตัวเลือก (คน) | H4: ดัชนีและการแปลผลทางสถิติ
A5: ข้อที่ | B5: เฉลย | C5: สาระการเรียนรู้ / เรื่องที่วัดผล | D5: เลือก ก | E5: เลือก ข | F5: เลือก ค | G5: เลือก ง | H5: ตอบถูก (คน) | I5: ค่าความยาก (P) | J5: การแปลผลระดับความยาก
A6: 1 | B6: ข | C6: หน่วยที่ 1: ความหมาย Information Architecture | D6: 10 | E6: 15 | F6: 2 | G6: 4 | H6: 15 | I6: 0.484 | J6: ยากปานกลาง (Optimal / Good)
A7: 2 | B7: ก | C7: หน่วยที่ 1: หลักการ Categorization | D7: 15 | E7: 5 | F7: 10 | G7: 1 | H7: 15 | I7: 0.484 | J7: ยากปานกลาง (Optimal / Good)
A8: 3 | B8: ค | C8: หน่วยที่ 1: หลักการ Labeling | D8: 3 | E8: 3 | F8: 23 | G8: 2 | H8: 23 | I8: 0.742 | J8: ค่อนข้างง่าย (Fairly Easy)
A9: 4 | B9: ง | C9: หน่วยที่ 1: User Journey vs User Flow | D9: 2 | E9: 6 | F9: 0 | G9: 23 | H9: 23 | I9: 0.742 | J9: ค่อนข้างง่าย (Fairly Easy)
A10: 5 | B10: ข | C10: หน่วยที่ 1: การเขียนผัง User Flow | D10: 8 | E10: 21 | F10: 1 | G10: 1 | H10: 21 | I10: 0.677 | J10: ค่อนข้างง่าย (Fairly Easy)
A11: 6 | B11: ก | C11: หน่วยที่ 1: บทบาทของแผนผังเว็บไซต์ (Sitemap) | D11: 25 | E11: 1 | F11: 3 | G11: 2 | H11: 25 | I11: 0.806 | J11: ง่ายมาก (Very Easy)
A12: 7 | B12: ค | C12: หน่วยที่ 1: เหตุผลที่ Wireframe ใช้ขาว-ดำ | D12: 3 | E12: 6 | F12: 12 | G12: 10 | H12: 12 | I12: 0.387 | J12: ค่อนข้างยาก (Fairly Hard)
A13: 8 | B13: ข | C13: หน่วยที่ 1: ข้อดีของการร่าง Wireframe | D13: 2 | E13: 22 | F13: 5 | G13: 2 | H13: 22 | I13: 0.71 | J13: ค่อนข้างง่าย (Fairly Easy)
A14: 9 | B14: ง | C14: หน่วยที่ 1: องค์ประกอบที่ไม่ควรมีใน Wireframe | D14: 4 | E14: 4 | F14: 5 | G14: 18 | H14: 18 | I14: 0.581 | J14: ยากปานกลาง (Optimal / Good)
A15: 10 | B15: ก | C15: หน่วยที่ 1: หัวใจหลักของ Blueprint (Wireframe) | D15: 24 | E15: 5 | F15: 0 | G15: 2 | H15: 24 | I15: 0.774 | J15: ค่อนข้างง่าย (Fairly Easy)
A16: 11 | B16: ค | C16: หน่วยที่ 2: แม่สีและการผสมสีขั้นที่ 2 | D16: 3 | E16: 4 | F16: 19 | G16: 5 | H16: 19 | I16: 0.613 | J16: ค่อนข้างง่าย (Fairly Easy)
A17: 12 | B17: ข | C17: หน่วยที่ 2: สีวรรณะกึ่งกลาง (Neutral Temperature) | D17: 6 | E17: 9 | F17: 7 | G17: 9 | H17: 9 | I17: 0.29 | J17: ค่อนข้างยาก (Fairly Hard)
... A35: 30 | B35: ค | C35: หน่วยที่ 3: กฎ 8pt Spacing System | D35: 4 | E35: 6 | F35: 13 | G35: 8 | H35: 13 | I35: 0.419 | J35: ยากปานกลาง (Optimal / Good)
A36: - | B36: - | C36: ค่าเฉลี่ยดัชนีความยากง่ายทั้งฉบับ | H36: =ROUND(AVERAGE(H6:H35), 2) | I36: =ROUND(AVERAGE(I6:I35), 3) | J36: ยากปานกลาง (เหมาะสมดีมาก)

Sheet เฉลยและเกณฑ์การให้คะแนน
A1: 📖 คู่มือเฉลยข้อสอบและคำอธิบายเชิงวิชาการอย่างละเอียด
A2: รหัสวิชา 21909-1006 วิชา พื้นฐานการสร้างเว็บไซต์ | ตอนที่ 1 แบบทดสอบปรนัย (30 ข้อ 30 คะแนน)
A4: ข้อที่ | B4: เฉลย | C4: สาระการเรียนรู้ / หน่วย | D4: คำอธิบายเหตุผลเฉลยตามเกณฑ์หลักสูตร
A5: 1 | B5: ข | C5: หน่วยที่ 1: ความหมาย Information Architecture | D5: IA คือกระบวนการจัดระเบียบ จัดหมวดหมู่ และวางโครงสร้างลำดับชั้นของข้อมูลในเว็บไซต์ เพื่อให้ผู้ใช้งานสามารถค้นหาข้อมูลที่ต้องการได้อย่างสะดวก รวดเร็ว และไม่สับสน
A6: 2 | B6: ก | C6: หน่วยที่ 1: หลักการ Categorization | D6: การนำข้อมูลประเภทเดียวกัน เช่น เสื้อผ้า รองเท้า อุปกรณ์ มารวบรวมไว้เป็นกลุ่มเดียวกัน เป็นนิยามตรงตัวของหลักการ Categorization (การจัดกลุ่มข้อมูล)
A7: 3 | B7: ค | C7: หน่วยที่ 1: หลักการ Labeling | D7: การตั้งชื่อฉลากหรือเมนูที่ดีตามหลัก UX ต้องใช้คำศัพท์ที่เรียบง่าย สื่อความหมายตรงไปตรงมา และตรงกับความเข้าใจของผู้ใช้ทั่วไป เช่น 'ค้นหาสินค้า' ไม่ควรใช้ศัพท์เทคนิคเชิงโปรแกรมมิ่ง
A8: 4 | B8: ง | C8: หน่วยที่ 1: User Journey vs User Flow | D8: User Journey คือภาพรวมประสบการณ์ อารมณ์ และความรู้สึกของผู้ใช้ตลอดเส้นทาง ส่วน User Flow คือผังแสดงขั้นตอนการทำงานเชิงเทคนิค (Step-by-Step Diagram) ว่าต้องคลิกผ่านหน้าจอใดบ้าง
A9: 5 | B9: ข | C9: หน่วยที่ 1: การเขียนผัง User Flow | D9: ผัง User Flow มุ่งเน้นแสดงขั้นตอนการตัดสินใจ (Decision Point) และเส้นทางการคลิกของยูสเซอร์ เช่น เงื่อนไขตรวจสอบสถานะล็อกอิน เพื่อนำทางไปยังหน้าจอถัดไปที่ถูกต้อง
A10: 6 | B10: ก | C10: หน่วยที่ 1: บทบาทของแผนผังเว็บไซต์ (Sitemap) | D10: Sitemap เป็นแผนภาพแสดงความสัมพันธ์ระหว่างหน้าทั้งหมดในเว็บไซต์ เพื่อให้เห็นโครงสร้างภาพรวมของระบบก่อนที่จะเริ่มลงมือออกแบบและเขียนโค้ดจริง
A11: 7 | B11: ค | C11: หน่วยที่ 1: เหตุผลที่ Wireframe ใช้ขาว-ดำ | D11: การลงสีสวยงามตั้งแต่แรกจะทำให้ผู้ใช้หรือลูกค้าหลอกตาและหลงประเด็น (เช่น โฟกัสเรื่องสีปุ่มมากกว่าหน้าที่ของปุ่ม) การใช้ขาว-ดำ-เทาจึงช่วยให้ทุกคนโฟกัสที่ Layout และ Functionality
A12: 8 | B12: ข | C12: หน่วยที่ 1: ข้อดีของการร่าง Wireframe | D12: การปรับเปลี่ยนโครงสร้างหน้าเว็บบน Wireframe ทำได้รวดเร็วและใช้ต้นทุนต่ำมาก หากไปรื้อแก้ไขหลังจากทำ Hi-Fi Mockup หรือเขียนโค้ดเสร็จแล้ว จะต้องเสียเวลาและแรงงานมากกว่ามหาศาล
A13: 9 | B13: ง | C13: หน่วยที่ 1: องค์ประกอบที่ไม่ควรมีใน Wireframe | D13: รูปภาพถ่ายจริงความละเอียดสูงและตกแต่งสีสันสมบูรณ์ เป็นองค์ประกอบของขั้นตอน High-Fidelity Mockup ไม่ควรนำมาใส่ในขั้นตอน Low-Fidelity Wireframe
A14: 10 | B14: ก | C14: หน่วยที่ 1: หัวใจหลักของ Blueprint (Wireframe) | D14: Wireframe ทำหน้าที่เป็นแบบแปลน (Blueprint) จึงต้องเน้น 3 ด้านหลัก ได้แก่ ตำแหน่งข้อมูล (Layout), ลำดับความสำคัญ (Hierarchy) และฟังก์ชันการทำงาน (Functionality)
A15: 11 | B15: ค | C15: หน่วยที่ 2: แม่สีและการผสมสีขั้นที่ 2 | D15: ในวงจรสี (Color Wheel) แม่สีขั้นที่ 1 ได้แก่ แดง เหลือง น้ำเงิน โดย สีแดง + สีน้ำเงิน = สีม่วง ซึ่งเป็นสีขั้นที่ 2 (Secondary Color)
A16: 12 | B16: ข | C16: หน่วยที่ 2: สีวรรณะกึ่งกลาง (Neutral Temperature) | D16: สีเหลืองและสีม่วง เป็นสีที่อยู่ตรงรอยต่อระหว่างวรรณะร้อนและวรรณะเย็น สามารถเปลี่ยนวรรณะไปตามสีแวดล้อมที่อยู่รอบข้างได้
... A34: 30 | B34: ค | C34: หน่วยที่ 3: กฎ 8pt Spacing System | D34: ในระบบ 8pt Spacing System ค่าตัวเลขต้องเป็นพหุคูณที่หารด้วย 8 ลงตัวเสมอ (เช่น 8px, 16px, 24px, 32px, 40px, 48px) ดังนั้น 22px จึงไม่สอดคล้องกับระบบนี้
